Workbook

Sheet Instructions
A6: Instructions
A8: 1.) Find a quiet place and allow yourself the full four hour exam period to practice. Treat this just as you would the real exam.
A10: 2.) Use the question hyperlinks on the Point Grid worksheet to navigate between questions in your preferred order.
A12: 3.) Answer each question either to the side or below the grey question area.
A14: 4.) Use cell B1 on each question worksheet to mark whether you finished the question or not. You should use this feature to
A15: reflect your confidence in your answer. This way you'll know if you're on the money or your guesses were lucky.
A17: 5.) Grade each question harshly. It's better to put in extra reviewing time now than find the examiners aren't as generous as you hoped.
A18: Use increments of 0.25 when scoring; pay attention to the language used in the question and the point value. An "identify" question
A19: is likely 0.25 per item while an "explain" or "briefly justify" gets 0.25 for the item and another 0.25 for the justification.
A21: 6.) Enter your estimated score for each sub-part of a question in the box beneath the sub-part point value. They look like:
A23: 7.) Return to the Point Grid to see your score and a breakdown of where you scored well and where you didn't.
A25: 8.) Find the top five questions where you lost the most points. These are the topics you need to review the most intensely in the
... A28: slay the beast

Sheet Point Grid
L2: Pts Achieved | M2: {=IF(SUM(IF(M8:S32="",0,1))=0,"",SUM(M8:S32))} | O2: Percentage: | P2: =IF(M2="","",M2/M3)
L3: Pts Available | M3: =SUM(B8:B37) -> 60
A5: Exam 5 - Practice 01 - Answers
B6: Total Point Value | C6: Sub-Part of Question | L6: Your Score | M6: Sub-Part of Question
A7: Question | C7: (a) | D7: (b) | E7: (c) | F7: (d) | G7: (e) | H7: (f) | I7: (g) | J7: Status | L7: Question | M7: (a) | N7: (b) | O7: (c) | P7: (d) | Q7: (e) | R7: (f) | S7: (g)
A8: 1 | B8: =SUM(C8:I8) -> 1 | C8: 1 | J8: =INDIRECT("'"&A8&"'!B1") -> Incomplete | L8: =A8 -> 1 | M8: =IF('1'!$A$8="","",'1'!$A$8)
A9: 2 | B9: =SUM(C9:I9) -> 1 | C9: 1 | J9: =INDIRECT("'"&A9&"'!B1") -> Incomplete | L9: =A9 -> 2 | M9: =IF('2'!$A$8="","",'2'!$A$8)
A10: 3 | B10: =SUM(C10:I10) -> 1 | C10: 1 | J10: =INDIRECT("'"&A10&"'!B1") -> Incomplete | L10: =A10 -> 3 | M10: =IF('3'!$A$8="","",'3'!$A$8)
A11: 4 | B11: =SUM(C11:I11) -> 1 | C11: 1 | J11: =INDIRECT("'"&A11&"'!B1") -> Incomplete | L11: =A11 -> 4 | M11: =IF('4'!$A$8="","",'4'!$A$8)
A12: 5 | B12: =SUM(C12:I12) -> 1 | C12: 1 | J12: =INDIRECT("'"&A12&"'!B1") -> Incomplete | L12: =A12 -> 5 | M12: =IF('5'!$A$8="","",'5'!$A$8)
A13: 6 | B13: =SUM(C13:I13) -> 1 | C13: 1 | J13: =INDIRECT("'"&A13&"'!B1") -> Incomplete | L13: =A13 -> 6 | M13: =IF('6'!$A$8="","",'6'!$A$8)
A14: 7 | B14: =SUM(C14:I14) -> 2 | C14: 0.75 | D14: 0.75 | E14: 0.5 | J14: =INDIRECT("'"&A14&"'!B1") -> Incomplete | L14: =A14 -> 7 | M14: =IF('7'!$A$8="","",'7'!$A$8) | N14: =IF('7'!$A$12="","",'7'!$A$12) | O14: =IF('7'!$A$16="","",'7'!$A$16)
A15: 8 | B15: =SUM(C15:I15) -> 2.5 | C15: 2 | D15: 0.5 | J15: =INDIRECT("'"&A15&"'!B1") -> Incomplete | L15: =A15 -> 8 | M15: =IF('8'!$A$8="","",'8'!$A$8) | N15: =IF('8'!$A$15="","",'8'!$A$15)
A16: 9 | B16: =SUM(C16:I16) -> 2.5 | C16: 0.5 | D16: 2 | J16: =INDIRECT("'"&A16&"'!B1") -> Incomplete | L16: =A16 -> 9 | M16: =IF('9'!$A$8="","",'9'!$A$8) | N16: =IF('9'!$A$12="","",'9'!$A$12)
A17: 10 | B17: =SUM(C17:I17) -> 2 | C17: 1 | D17: 1 | J17: =INDIRECT("'"&A17&"'!B1") -> Incomplete | L17: =A17 -> 10 | M17: =IF('10'!$A$8="","",'10'!$A$8) | N17: =IF('10'!$A$12="","",'10'!$A$12)
A18: 11 | B18: =SUM(C18:I18) -> 1.5 | C18: 1 | D18: 0.5 | J18: =INDIRECT("'"&A18&"'!B1") -> Incomplete | L18: =A18 -> 11 | M18: =IF('11'!$A$8="","",'11'!$A$8) | N18: =IF('11'!$A$16="","",'11'!$A$16)
A19: 12 | B19: =SUM(C19:I19) -> 3.25 | C19: 2 | D19: 0.5 | E19: 0.75 | J19: =INDIRECT("'"&A19&"'!B1") -> Incomplete | L19: =A19 -> 12 | M19: =IF('12'!$A$8="","",'12'!$A$8) | N19: =IF('12'!$A$12="","",'12'!$A$12) | O19: =IF('12'!$A$16="","",'12'!$A$16)
A20: 13 | B20: =SUM(C20:I20) -> 3.75 | C20: 1 | D20: 1.25 | E20: 1.5 | J20: =INDIRECT("'"&A20&"'!B1") -> Incomplete | L20: =A20 -> 13 | M20: =IF('13'!$A$8="","",'13'!$A$8) | N20: =IF('13'!$A$12="","",'13'!$A$12) | O20: =IF('13'!$A$31="","",'13'!$A$31)
A21: 14 | B21: =SUM(C21:I21) -> 2 | C21: 2 | J21: =INDIRECT("'"&A21&"'!B1") -> Incomplete | L21: =A21 -> 14 | M21: =IF('14'!$A$8="","",'14'!$A$8)
A22: 15 | B22: =SUM(C22:I22) -> 1.25 | C22: 1.25 | J22: =INDIRECT("'"&A22&"'!B1") -> Incomplete | L22: =A22 -> 15 | M22: =IF('15'!$A$8="","",'15'!$A$8)
A23: 16 | B23: =SUM(C23:I23) -> 2.5 | C23: 0.25 | D23: 0.5 | E23: 0.75 | F23: 1 | J23: =INDIRECT("'"&A23&"'!B1") -> Incomplete | L23: =A23 -> 16 | M23: =IF('16'!$A$8="","",'16'!$A$8) | N23: =IF('16'!$A$12="","",'16'!$A$12) | O23: =IF('16'!$A$16="","",'16'!$A$16) | P23: =IF('16'!$A$20="","",'16'!$A$20)
A24: 17 | B24: =SUM(C24:I24) -> 2.75 | C24: 0.5 | D24: 1.5 | E24: 0.75 | J24: =INDIRECT("'"&A24&"'!B1") -> Incomplete | L24: =A24 -> 17 | M24: =IF('17'!$A$8="","",'17'!$A$8) | N24: =IF('17'!$A$12="","",'17'!$A$12) | O24: =IF('17'!$A$16="","",'17'!$A$16)
A25: 18 | B25: =SUM(C25:I25) -> 1 | C25: 0.75 | D25: 0.25 | J25: =INDIRECT("'"&A25&"'!B1") -> Incomplete | L25: =A25 -> 18 | M25: =IF('18'!$A$8="","",'18'!$A$8) | N25: =IF('18'!$A$18="","",'18'!$A$18)
A26: 19 | B26: =SUM(C26:I26) -> 0.75 | C26: 0.75 | J26: =INDIRECT("'"&A26&"'!B1") -> Incomplete | L26: =A26 -> 19 | M26: =IF('19'!$A$8="","",'19'!$A$8)
A27: 20 | B27: =SUM(C27:I27) -> 1.5 | C27: 0.25 | D27: 0.25 | E27: 0.25 | F27: 0.25 | G27: 0.25 | H27: 0.25 | J27: =INDIRECT("'"&A27&"'!B1") -> Incomplete | L27: =A27 -> 20 | M27: =IF('20'!$A$8="","",'20'!$A$8) | N27: =IF('20'!$A$12="","",'20'!$A$12) | O27: =IF('20'!$A$16="","",'20'!$A$16) | P27: =IF('20'!$A$20="","",'20'!$A$20) | Q27: =IF('20'!$A$24="","",'20'!$A$24) | R27: =IF('20'!$A$28="","",'20'!$A$28)
A28: 21 | B28: =SUM(C28:I28) -> 2.25 | C28: 1 | D28: 0.25 | E28: 1 | J28: =INDIRECT("'"&A28&"'!B1") -> Incomplete | L28: =A28 -> 21 | M28: =IF('21'!$A$8="","",'21'!$A$8) | N28: =IF('21'!$A$22="","",'21'!$A$22) | O28: =IF('21'!$A$26="","",'21'!$A$26)
A29: 22 | B29: =SUM(C29:I29) -> 1.75 | C29: 0.25 | D29: 0.5 | E29: 1 | J29: =INDIRECT("'"&A29&"'!B1") -> Incomplete | L29: =A29 -> 22 | M29: =IF('22'!$A$8="","",'22'!$A$8) | N29: =IF('22'!$A$12="","",'22'!$A$12) | O29: =IF('22'!$A$16="","",'22'!$A$16)
A30: 23 | B30: =SUM(C30:I30) -> 3 | C30: 0.5 | D30: 1 | E30: 1.5 | J30: =INDIRECT("'"&A30&"'!B1") -> Incomplete | L30: =A30 -> 23 | M30: =IF('23'!$A$8="","",'23'!$A$8) | N30: =IF('23'!$A$12="","",'23'!$A$12) | O30: =IF('23'!$A$16="","",'23'!$A$16)
A31: 24 | B31: =SUM(C31:I31) -> 4.5 | C31: 1 | D31: 1 | E31: 2.5 | J31: =INDIRECT("'"&A31&"'!B1") -> Incomplete | L31: =A31 -> 24 | M31: =IF('24'!$A$8="","",'24'!$A$8) | N31: =IF('24'!$A$12="","",'24'!$A$12) | O31: =IF('24'!$A$16="","",'24'!$A$16)
A32: 25 | B32: =SUM(C32:I32) -> 2 | C32: 0.5 | D32: 1.5 | J32: =INDIRECT("'"&A32&"'!B1") -> Incomplete | L32: =A32 -> 25 | M32: =IF('25'!$A$8="","",'25'!$A$8) | N32: =IF('25'!$A$15="","",'25'!$A$15)
A33: 26 | B33: =SUM(C33:I33) -> 2.25 | C33: 0.25 | D33: 0.25 | E33: 1.75 | J33: =INDIRECT("'"&A33&"'!B1") -> Incomplete | L33: 26 | M33: =IF('26'!$A$8="","",'26'!$A$8) | N33: =IF('26'!$A$12="","",'26'!$A$12) | O33: =IF('26'!$A$16="","",'26'!$A$16)
A34: 27 | B34: =SUM(C34:I34) -> 1.5 | C34: 0.25 | D34: 0.25 | E34: 0.5 | F34: 0.5 | J34: =INDIRECT("'"&A34&"'!B1") -> Incomplete | L34: 27 | M34: =IF('27'!$A$8="","",'27'!$A$8) | N34: =IF('27'!$A$12="","",'27'!$A$12) | O34: =IF('27'!$A$16="","",'27'!$A$16) | P34: =IF('27'!$A$24="","",'27'!$A$24)
A35: 28 | B35: =SUM(C35:I35) -> 3 | C35: 0.5 | D35: 0.5 | E35: 0.5 | F35: 1.5 | J35: =INDIRECT("'"&A35&"'!B1") -> Incomplete | L35: 28 | M35: =IF('28'!$A$8="","",'28'!$A$8) | N35: =IF('28'!$A$23="","",'28'!$A$23) | O35: =IF('28'!$A$27="","",'28'!$A$27) | P35: =IF('28'!$A$39="","",'28'!$A$39)
A36: 29 | B36: =SUM(C36:I36) -> 2 | C36: 2 | J36: =INDIRECT("'"&A36&"'!B1") -> Incomplete | L36: 29 | M36: =IF('29'!$A$8="","",'29'!$A$8)
A37: 30 | B37: =SUM(C37:I37) -> 2.5 | C37: 0.75 | D37: 1.75 | J37: =INDIRECT("'"&A37&"'!B1") -> Incomplete | L37: 30 | M37: =IF('30'!$A$8="","",'30'!$A$8) | N37: =IF('30'!$A$12="","",'30'!$A$12)

Sheet 1
A1: 1 | B1: Incomplete | H1: Return to Point Grid
A3: Points
A4: =INDEX('Point Grid'!B:B,MATCH('1'!A1,'Point Grid'!A:A,0)) -> 1 | B4: Select the best answer to the following question.
A6: (a) | B6: Which category of expenses directly relates to investigating and settling insurance claims?
A7: =INDEX('Point Grid'!$C$8:$I$54,MATCH($A$1,'Point Grid'!$A$8:$A$54,0),MATCH(A6,'Point Grid'!$C$7:$I$7,0)) -> 1
B11: (A) | C11: Loss Adjustment Expenses
B14: (B) | C14: Underwriting Expenses
B17: (C) | C17: Taxes, Licenses, and Fees
B20: (D) | C20: Administrative Costs

Sheet 2
A1: 2 | B1: Incomplete | H1: Return to Point Grid
A3: Points
A4: =INDEX('Point Grid'!B:B,MATCH(A1,'Point Grid'!A:A,0)) -> 1 | B4: Select the best answer to the following question.
A6: (a) | B6: What is the primary reason that ratemaking is considered prospective in property and casualty insurance?
A7: =INDEX('Point Grid'!$C$8:$I$54,MATCH($A$1,'Point Grid'!$A$8:$A$54,0),MATCH(A6,'Point Grid'!$C$7:$I$7,0)) -> 1
B11: (A) | C11: It is calculated after the transfer of risk.
B14: (B) | C14: It focuses only on past incidents.
B17: (C) | C17: It must be developed prior to the transfer of risk.
B20: (D) | C20: It is based on arbitrary numbers.

Sheet 3
A1: 3 | B1: Incomplete | H1: Return to Point Grid
A3: Points
A4: =INDEX('Point Grid'!B:B,MATCH(A1,'Point Grid'!A:A,0)) -> 1 | B4: Select the best answer to the following question.
A6: (a) | B6: What is an unpaid claims estimate or reserve in insurance?
A7: =INDEX('Point Grid'!$C$8:$I$54,MATCH($A$1,'Point Grid'!$A$8:$A$54,0),MATCH(A6,'Point Grid'!$C$7:$I$7,0)) -> 1
B11: (A) | C11: The total income received from policyholders.
B14: (B) | C14: The insurer's estimate for future administrative costs.
B17: (C) | C17: The actuary’s estimate of the obligation for future payment resulting from claims
C18: due to past events.
B20: (D) | C20: The total value of assets held by the insurer.

Sheet 4
A1: 4 | B1: Incomplete | H1: Return to Point Grid
A3: Points
A4: =INDEX('Point Grid'!B:B,MATCH(A1,'Point Grid'!A:A,0)) -> 1 | B4: Select the best answer to the following question.
A6: (a) | B6: For whom are accurate reserve estimates important, and why is accuracy crucial ?
A7: =INDEX('Point Grid'!$C$8:$I$54,MATCH($A$1,'Point Grid'!$A$8:$A$54,0),MATCH(A6,'Point Grid'!$C$7:$I$7,0)) -> 1
B11: (A) | C11: Policyholders - for getting lower premiums.
B14: (B) | C14: Internal management - for proper decision-making like pricing and strategic plans.
B17: (C) | C17: Competitors - to understand market trends.
B20: (D) | C20: Government - for tax purposes.

Sheet 5
A1: 5 | B1: Incomplete | H1: Return to Point Grid
A3: Points
A4: =INDEX('Point Grid'!B:B,MATCH(A1,'Point Grid'!A:A,0)) -> 1 | B4: Enter your answer in the space provided.
A6: (a) | B6: Calculate the retention ratio.
A7: =INDEX('Point Grid'!$C$8:$I$54,MATCH($A$1,'Point Grid'!$A$8:$A$54,0),MATCH(A6,'Point Grid'!$C$7:$I$7,0)) -> 1
B8: Answer:
B10: counts | E10: 9
B11: Exposures (X) | E11: 100
B12: Losses (L) | E12: 53100
B13: Earned Premium (EP) | E13: 73800
B14: Written Premium (WP) | E14: 90000
B15: Loss Adjustment Expense (LAE) | E15: 14300
B16: Comm, Other, TLF | E16: 8100
B17: General Expense | E17: 2950
B18: # of policies renewed | E18: 56
B19: # of potential renewals | E19: 100
B20: # of accepted quotes | E20: 101
B21: # of quotes | E21: 150
B34: counts | C34: 9
B35: Exposures (X) | C35: 100
B36: Losses (L) | C36: 53100
B37: Earned Premium (EP) | C37: 73800
B38: Written Premium (WP) | C38: 90000
B39: Loss Adjustment Expense (LAE) | C39: 14300
B40: Comm, Other, TLF | C40: 8100
B41: General Expense | C41: 2950
B42: # of policies renewed | C42: 56
B43: # of potential renewals | C43: 100
B44: # of accepted quotes | C44: 101
B45: # of quotes | C45: 150

Sheet 6
A1: 6 | B1: Incomplete | H1: Return to Point Grid
A3: Points
A4: =INDEX('Point Grid'!B:B,MATCH(A1,'Point Grid'!A:A,0)) -> 1 | B4: Enter your answer in the space provided.
A6: (a) | B6: Calculate the cumulative reported loss at time t2.
A7: =INDEX('Point Grid'!$C$8:$I$54,MATCH($A$1,'Point Grid'!$A$8:$A$54,0),MATCH(A6,'Point Grid'!$C$7:$I$7,0)) -> 1
B8: Answer:
B10: incremental reported loss from time t1 to time t2 | F10: 100
B11: cumulative reported loss at time t1 | F11: 980

Sheet 7
A1: 7 | B1: Incomplete | H1: Return to Point Grid
A3: Points
A4: =INDEX('Point Grid'!B:B,MATCH(A1,'Point Grid'!A:A,0)) -> 2
A6: (a) | B6: Calendar year aggregation is one way of aggregating loss data. Identify 3 other common ways
A7: =INDEX('Point Grid'!$C$8:$I$54,MATCH($A$1,'Point Grid'!$A$8:$A$54,0),MATCH(A6,'Point Grid'!$C$7:$I$7,0)) -> 0.75 | B7: of aggregating loss data.
A10: (b) | B10: Identify 3 criteria that a good exposure base should satisfy.
A11: =INDEX('Point Grid'!$C$8:$I$54,MATCH($A$1,'Point Grid'!$A$8:$A$54,0),MATCH(A10,'Point Grid'!$C$7:$I$7,0)) -> 0.75
A14: (c) | B14: Suppose there are four 12-month auto insurance policies each with an effective date of August 1, 2023.
A15: =INDEX('Point Grid'!$C$8:$I$54,MATCH($A$1,'Point Grid'!$A$8:$A$54,0),MATCH(A14,'Point Grid'!$C$7:$I$7,0)) -> 0.5 | B15: Calculate the following quantities:
B17: (i) | C17: Written exposures for calendar year 2023
B18: (ii) | C18: In-force exposures as of July 15, 2025

Sheet 8
A1: 8 | B1: Incomplete | H1: Return to Point Grid
A3: Points
A4: =INDEX('Point Grid'!B:B,MATCH(A1,'Point Grid'!A:A,0)) -> 2.5
A6: (a) | B6: Calculate the EP @ CRL for CY 2020 and 2021 assuming annual policies and 1 rate change.
A7: =INDEX('Point Grid'!$C$8:$I$54,MATCH($A$1,'Point Grid'!$A$8:$A$54,0),MATCH(A6,'Point Grid'!$C$7:$I$7,0)) -> 2
C8: EP for CY 2020 | E8: 120
C9: EP for CY 2021 | E9: 210
C10: rate change | E10: -0.09
C11: rate change date | E11: 44378
A13: (b) | B13: Identify 2 adjustments, other than bringing premiums to curent rate level, that may be required
A14: =INDEX('Point Grid'!$C$8:$I$54,MATCH($A$1,'Point Grid'!$A$8:$A$54,0),MATCH(A13,'Point Grid'!$C$7:$I$7,0)) -> 0.5 | B14: before using premium in a rate indication.

Sheet 9
A1: 9 | B1: Incomplete | H1: Return to Point Grid
A3: Points
A4: =INDEX('Point Grid'!B:B,MATCH(A1,'Point Grid'!A:A,0)) -> 2.5
A6: (a) | B6: Large individual losses, also called shock losses, happen infrequently but can cause instability in
A7: =INDEX('Point Grid'!$C$8:$I$54,MATCH($A$1,'Point Grid'!$A$8:$A$54,0),MATCH(A6,'Point Grid'!$C$7:$I$7,0)) -> 0.5 | B7: the ratemaking process. Identify 2 principles in determining a shock loss threshold.
A10: (b) | B10: Given the following loss information, calculate the excess loss factor (excess ratio) for AY 2025.
A11: =INDEX('Point Grid'!$C$8:$I$54,MATCH($A$1,'Point Grid'!$A$8:$A$54,0),MATCH(A10,'Point Grid'!$C$7:$I$7,0)) -> 2
C12: Large Loss Threshold: | E12: =250 -> 250
D14: Reported | E14: # of Excess | F14: Ground-up
C15: AY | D15: Loss | E15: Claims | F15: Excess Losses
C16: 2022 | D16: 19000 | E16: 5 | F16: 3255
C17: 2023 | D17: 26400 | E17: 0 | F17: 0
C18: 2024 | D18: 22880 | E18: 1 | F18: 1151
C19: 2025 | D19: 21964 | E19: 22 | F19: 8095
C20: Total | D20: 90244 | E20: 28 | F20: 12501

Sheet 10
A1: 10 | B1: Incomplete | H1: Return to Point Grid
A3: Points
A4: =INDEX('Point Grid'!B:B,MATCH(A1,'Point Grid'!A:A,0)) -> 2
A6: (a) | B6: Identify and briefly describe the 4 categories of underwriting expenses relevant to performing a rate
A7: =INDEX('Point Grid'!$C$8:$I$54,MATCH($A$1,'Point Grid'!$A$8:$A$54,0),MATCH(A6,'Point Grid'!$C$7:$I$7,0)) -> 1 | B7: indication.
A10: (b) | B10: Calculate the average premium an insurer must charge to balance the Fundamental Insurance Equation.
A11: =INDEX('Point Grid'!$C$8:$I$54,MATCH($A$1,'Point Grid'!$A$8:$A$54,0),MATCH(A10,'Point Grid'!$C$7:$I$7,0)) -> 1
C12: loss | F12: 114700
C13: LAE | F13: 27080
C14: fixed U/W expense | F14: 17520
C15: exposures | F15: 540
C16: variable expense provision | F16: 0.18 | G16: = V
C17: target profit percentage | F17: 0.05 | G17: = QT

Sheet 11
A1: 11 | B1: Incomplete | H1: Return to Point Grid
A3: Points
A4: =INDEX('Point Grid'!B:B,MATCH(A1,'Point Grid'!A:A,0)) -> 1.5
A6: (a) | B6: Calculate the indicated average rate level change.
A7: =INDEX('Point Grid'!$C$8:$I$54,MATCH($A$1,'Point Grid'!$A$8:$A$54,0),MATCH(A6,'Point Grid'!$C$7:$I$7,0)) -> 1
C8: experience period on-level trended EP | H8: 441000
C9: experience period trended & developed Loss & LAE | H9: 339570
C10: experience period fixed expenses | H10: 13671
C11: variable expense provision | H11: 0.2
C12: target profit percentage | H12: 0.04
A14: (b) | B14: The loss ratio method for calculating an indicated rate change requires premium data and provides
A15: =INDEX('Point Grid'!$C$8:$I$54,MATCH($A$1,'Point Grid'!$A$8:$A$54,0),MATCH(A14,'Point Grid'!$C$7:$I$7,0)) -> 0.5 | B15: the indicated percentage rate change. What data does the pure premium method require, and what
B16: output result does it provide?

Sheet 12
A1: 12 | B1: Incomplete | L1: Return to Point Grid
A3: Points
A4: =INDEX('Point Grid'!B:B,MATCH(A1,'Point Grid'!A:A,0)) -> 3.25
A6: (a) | B6: Using the information shown further down, calculate the developed and trended losses & LAE by
A7: =INDEX('Point Grid'!$C$8:$I$54,MATCH($A$1,'Point Grid'!$A$8:$A$54,0),MATCH(A6,'Point Grid'!$C$7:$I$7,0)) -> 2 | B7: accident year.
A10: (b) | B10: Using the information shown further down, calculate the indicated pure premium.
A11: =INDEX('Point Grid'!$C$8:$I$54,MATCH($A$1,'Point Grid'!$A$8:$A$54,0),MATCH(A10,'Point Grid'!$C$7:$I$7,0)) -> 0.5
A14: (c) | B14: Using the information shown further down, calculate the indicated rate.
A15: =INDEX('Point Grid'!$C$8:$I$54,MATCH($A$1,'Point Grid'!$A$8:$A$54,0),MATCH(A14,'Point Grid'!$C$7:$I$7,0)) -> 0.75
B18: Losses as of yr-end: | D18: 2028 | F18: LDFs (Loss & LAE): | I18: Expenses / Profit:
C20: Reported | D20: Earned
B21: CY / AY | C21: Loss & LAE | D21: Exposures | F21: 12-Ult | G21: 2.4 | I21: Commission | K21: 0.1
B22: 2025 | C22: 5204000 | D22: 16100 | F22: 24-Ult | G22: 1.48 | I22: Taxes | K22: 0.04
B23: 2026 | C23: 5412000 | D23: 17100 | F23: 36-Ult | G23: 1.13 | I23: Variable Expenses 1 | K23: 0.1
B24: 2027 | C24: 5683000 | D24: 18500 | F24: 48-Ult | G24: 1.02 | I24: Fixed Expense | K24: 35
B25: 2028 | C25: 6024000 | D25: 20000 | F25: 60-Ult | G25: 1 | I25: Profit | K25: 0.04
B27: Trends are Exponential | I27: 1 Refers to variable portion of general
I28: and other acquisition expenses.
B29: Frequency Trend | D29: 0.04
B30: Severity Trend | D30: -0.01
B32: Other Information:
B34: effective date: | D34: 2029 | E34: 10 | F34: 1 | G34: <== (year, month, day)
B35: rates in effect for | D35: 18 | E35: months
B36: policy term: | D36: 12 | E36: months

Sheet 13
A1: 13 | B1: Incomplete | H1: Return to Point Grid
A3: Points
A4: =INDEX('Point Grid'!B:B,MATCH(A1,'Point Grid'!A:A,0)) -> 3.75
A6: (a) | B6: "Legal criteria" are ways of evaluating rating variables. For example, a rating variable must follow all
A7: =INDEX('Point Grid'!$C$8:$I$54,MATCH($A$1,'Point Grid'!$A$8:$A$54,0),MATCH(A6,'Point Grid'!$C$7:$I$7,0)) -> 1 | B7: appropriate laws and regulations. Identify 2 other criteria and provide a brief description of each.
A10: (b) | B10: Match each type of insurance listed below with the rating variable list that best goes with each. For
A11: =INDEX('Point Grid'!$C$8:$I$54,MATCH($A$1,'Point Grid'!$A$8:$A$54,0),MATCH(A10,'Point Grid'!$C$7:$I$7,0)) -> 1.25 | B11: example, "Commercial Auto" corresponds to "Driver Class, Territory, Limit of Liability" so you would
B12: answer "6-B".
C13: Type of Insurance
B14: 1 | C14: Personal Auto
B15: 2 | C15: Homeowners
B16: 3 | C16: Workers Compensation
B17: 4 | C17: Commercial General Liability
B18: 5 | C18: Medical Malpractice
B19: 6 | C19: Commercial Auto
C21: Rating Variables
B22: A | C22: Occupation Class Code
B23: B | C23: Driver Class, Territory, Limit of Liability
B24: C | C24: Driver Age & Gender, Model Year, Accident History
B25: D | C25: Specialty, Territory, Limit of Liability
B26: E | C26: Classification, Territory, Limit of Liability
B27: F | C27: Amount of Insurance, Age of Home, Construction Type
A29: (c) | B29: Propose rating factors for the given rating variable relative to the base class: | H29: 1
A30: =INDEX('Point Grid'!$C$8:$I$54,MATCH($A$1,'Point Grid'!$A$8:$A$54,0),MATCH(A29,'Point Grid'!$C$7:$I$7,0)) -> 1.5
C31: level
C32: of | E32: reported
C33: variable | D33: EE | E33: L + ALAE
C34: 1 | D34: 195 | E34: 74100
C35: 2 | D35: 423 | E35: 279180
C36: 3 | D36: 224 | E36: 176960

Sheet 14
A1: 14 | B1: Incomplete | L1: Return to Point Grid
A3: Points
A4: =INDEX('Point Grid'!B:B,MATCH(A1,'Point Grid'!A:A,0)) -> 2
A6: (a) | B6: An insurer is considering using credit score to further segment its homeowners book of business.
A7: =INDEX('Point Grid'!$C$8:$I$54,MATCH($A$1,'Point Grid'!$A$8:$A$54,0),MATCH(A6,'Point Grid'!$C$7:$I$7,0)) -> 2 | B7: The insurer has developed a generalized linear model to evaluate different variables’ contribution to
B8: expected frequency of wind claims.
B10: The first diagnostic chart displays the results of a countrywide analysis performed on 1 year of
B11: data from a generalized linear model:
B13: The second diagnostic chart displays the results of a countrywide analysis performed on 5 years of
B14: data from a generalized linear model. (The year of the 5 years of data incorporate the same 1 year of
B15: data used for the original multivaraite analysis.)
B17: Based on the first chart, the actuarial department recommended that credit score should not be used as a rating
B18: variable. Based on the second analysis 4 years later however, the actuarial department changed their
B19: recommendation and now advise that credit score should be used as a rating variable.
B21: Identify and briefly describe 2 reasons for the actuarial's departement change in recommendation.
B23: First analysis using 1 year of data:
C27: 1.0 | K27: 100
C29: Frequency | K29: Exposures
C31: 0.5 | I31: x | K31: 50
G32: x
E33: x
C35: 0.0 | K35: 0
E36: Good | G36: Fair | I36: Poor
G37: CREDIT SCORE
G39: x
E40: (Exposures) | G40: (Indicated Relativity) | J40: (+/- 2 Standard Errors)
B42: Second analysis using 5 years of data:
C46: 1.0 | K46: 800
I47: x
C48: Frequency | K48: Exposures
C50: 0.5 | G50: x | K50: 400
E52: x
C54: 0.0 | K54: 0
E55: Good | G55: Fair | I55: Poor
G56: CREDIT SCORE
G58: x
E59: (Exposures) | G59: (Indicated Relativity) | J59: (+/- 2 Standard Errors)

Sheet 15
A1: 15 | B1: Incomplete | H1: Return to Point Grid
A3: Points
A4: =INDEX('Point Grid'!B:B,MATCH(A1,'Point Grid'!A:A,0)) -> 1.25
A6: (a) | B6: Calculate the increased limits factors for a a limit of: | F6: 50
A7: =INDEX('Point Grid'!$C$8:$I$54,MATCH($A$1,'Point Grid'!$A$8:$A$54,0),MATCH(A6,'Point Grid'!$C$7:$I$7,0)) -> 1.25
B9: Basic policy limit: | D9: 10
B11: loss range
B12: lower | C12: upper | D12: reported | E12: reported
B13: limit | C13: limit | D13: counts | E13: loss
B14: 0 | C14: 10 | D14: 140 | E14: 810
B15: 10 | C15: 25 | D15: 70 | E15: 730
B16: 25 | C16: 50 | D16: 55 | E16: 2680
B17: 50 | C17: 100 | D17: 30 | E17: 2840
B18: 100 | C18: 300 | D18: 14 | E18: 2610

Sheet 16
A1: 16 | B1: Incomplete | H1: Return to Point Grid
A3: Points
A4: =INDEX('Point Grid'!B:B,MATCH(A1,'Point Grid'!A:A,0)) -> 2.5
A6: (a) | B6: Define the term "Insurance-to-Value" as given in the Werner and Modlin text.
A7: =INDEX('Point Grid'!$C$8:$I$54,MATCH($A$1,'Point Grid'!$A$8:$A$54,0),MATCH(A6,'Point Grid'!$C$7:$I$7,0)) -> 0.25
A10: (b) | B10: Briefly explain the concept of a "coninsurance penalty".
A11: =INDEX('Point Grid'!$C$8:$I$54,MATCH($A$1,'Point Grid'!$A$8:$A$54,0),MATCH(A10,'Point Grid'!$C$7:$I$7,0)) -> 0.5
A14: (c) | B14: The Werner & Modlin source text discusses different way insurers can encourage customers to properly
A15: =INDEX('Point Grid'!$C$8:$I$54,MATCH($A$1,'Point Grid'!$A$8:$A$54,0),MATCH(A14,'Point Grid'!$C$7:$I$7,0)) -> 0.75 | B15: insure their properties. In other words, to buy a policy with a face value equal to the value of the
B16: properly. The source text calls these ITV-initiatives. Identify and briefly describe 3 of these initiatives.
A18: (d) | B18: Calculate the rate per $1,000 of coverage.
A19: =INDEX('Point Grid'!$C$8:$I$54,MATCH($A$1,'Point Grid'!$A$8:$A$54,0),MATCH(A18,'Point Grid'!$C$7:$I$7,0)) -> 1
C20: value of home | E20: 410000
C21: AOI | E21: 217300
C22: frequency of loss | E22: 0.02
B24: The severity of loss is uniformly distributed between 0 and the value of the home.

Sheet 17
A1: 17 | B1: Incomplete | H1: Return to Point Grid
A3: Points
A4: =INDEX('Point Grid'!B:B,MATCH(A1,'Point Grid'!A:A,0)) -> 2.75
A6: (a) | B6: State the Fundamental Insurance Equation.
A7: =INDEX('Point Grid'!$C$8:$I$54,MATCH($A$1,'Point Grid'!$A$8:$A$54,0),MATCH(A6,'Point Grid'!$C$7:$I$7,0)) -> 0.5
A10: (b) | B10: Identify and briefly describe 3 distinct non-pricing solutions for rebalancing the Fundamental
A11: =INDEX('Point Grid'!$C$8:$I$54,MATCH($A$1,'Point Grid'!$A$8:$A$54,0),MATCH(A10,'Point Grid'!$C$7:$I$7,0)) -> 1.5 | B11: Insurance Equation.
A14: (c) | B14: Calculate the fixed expense ratio:
A15: =INDEX('Point Grid'!$C$8:$I$54,MATCH($A$1,'Point Grid'!$A$8:$A$54,0),MATCH(A14,'Point Grid'!$C$7:$I$7,0)) -> 0.75
C16: countrywide premium ($000s) | F16: 6500
C17: profit provision | F17: 0.03
C18: average loss cost | F18: 370
C20: expense | E20: countrywide
C21: category | E21: expenses ($000s) | G21: %-fixed
C22: commissions | E22: 1600 | G22: 0
C23: general expenses | E23: 1000 | G23: 0.54
C24: other acquisition | E24: 400 | G24: 1
C25: taxes | E25: 400 | G25: 0
C26: licenses & fees | E26: 50 | G26: 1
C27: TOTAL | E27: 3450

Sheet 18
A1: 18 | B1: Incomplete | H1: Return to Point Grid
A3: Points
A4: =INDEX('Point Grid'!B:B,MATCH(A1,'Point Grid'!A:A,0)) -> 1
A6: (a) | B6: Given the following information for a retrospectively rated worker's compensation policy, calculate the
A7: =INDEX('Point Grid'!$C$8:$I$54,MATCH($A$1,'Point Grid'!$A$8:$A$54,0),MATCH(A6,'Point Grid'!$C$7:$I$7,0)) -> 0.75 | B7: final retrospective premium.
C9: Standard premium | G9: 658000
C10: Basic premium | G10: 212197
C11: Converted losses | G11: 163800
C12: Tax multiplier | G12: 1.02
C13: Minimum retrospective premium ratio | G13: 0.7
C14: Maximum retrospective premium ratio | G14: 1.3
A16: (b) | B16: One of the following statements applies to large deductible policies and the other to small
A17: =INDEX('Point Grid'!$C$8:$I$54,MATCH($A$1,'Point Grid'!$A$8:$A$54,0),MATCH(A16,'Point Grid'!$C$7:$I$7,0)) -> 0.25 | B17: deductible policies. Which is which?
B19: (i) | C19: policies that eliminate costs to the insurer for handling nuisance claims
B20: (ii) | C20: policies where the insured bears a significant portion of the risk

Sheet 19
A1: 19 | B1: Incomplete | H1: Return to Point Grid
A3: Points
A4: =INDEX('Point Grid'!B:B,MATCH(A1,'Point Grid'!A:A,0)) -> 0.75
A6: (a) | B6: How can a redundant claim estimate impact:
A7: =INDEX('Point Grid'!$C$8:$I$54,MATCH($A$1,'Point Grid'!$A$8:$A$54,0),MATCH(A6,'Point Grid'!$C$7:$I$7,0)) -> 0.75
B8: (i) | C8: management
B9: (ii) | C9: investors
B10: (iii) | C10: regulators

Sheet 20
A1: 20 | B1: Incomplete | K1: Return to Point Grid
A3: Points
A4: =INDEX('Point Grid'!B:B,MATCH(A1,'Point Grid'!A:A,0)) -> 1.5 | B4: Given the triangles shown further down, compute the following quantities:
A6: (a) | B6: cumulative paid loss for AY | E6: 2023 | F6: @ | G6: 36 | H6: months
A7: =INDEX('Point Grid'!$C$8:$I$54,MATCH($A$1,'Point Grid'!$A$8:$A$54,0),MATCH(A6,'Point Grid'!$C$7:$I$7,0)) -> 0.25
A10: (b) | B10: incremental paid loss for AY | E10: 2023 | F10: @ | G10: 12 | H10: months
A11: =INDEX('Point Grid'!$C$8:$I$54,MATCH($A$1,'Point Grid'!$A$8:$A$54,0),MATCH(A10,'Point Grid'!$C$7:$I$7,0)) -> 0.25
A14: (c) | B14: cumulative reported loss for AY | E14: 2022 | F14: @ | G14: 36 | H14: months
A15: =INDEX('Point Grid'!$C$8:$I$54,MATCH($A$1,'Point Grid'!$A$8:$A$54,0),MATCH(A14,'Point Grid'!$C$7:$I$7,0)) -> 0.25
A18: (d) | B18: incremental reported loss for AY | E18: 2022 | F18: @ | G18: 48 | H18: months
A19: =INDEX('Point Grid'!$C$8:$I$54,MATCH($A$1,'Point Grid'!$A$8:$A$54,0),MATCH(A18,'Point Grid'!$C$7:$I$7,0)) -> 0.25
A22: (e) | B22: cumulative reported count for AY | E22: 2022 | F22: @ | G22: 48 | H22: months
A23: =INDEX('Point Grid'!$C$8:$I$54,MATCH($A$1,'Point Grid'!$A$8:$A$54,0),MATCH(A22,'Point Grid'!$C$7:$I$7,0)) -> 0.25
A26: (f) | B26: total paid loss for CY | E26: 2023
A27: =INDEX('Point Grid'!$C$8:$I$54,MATCH($A$1,'Point Grid'!$A$8:$A$54,0),MATCH(A26,'Point Grid'!$C$7:$I$7,0)) -> 0.25
B30: Here is the triangle information:
B32: Amounts | C32: Paid Loss | E32: Development Age
B33: AY | C33: 12 | D33: =C33+12 -> 24 | E33: =D33+12 -> 36 | F33: =E33+12 -> 48 | G33: =F33+12 -> 60 | H33: =G33+12 -> 72
B34: 2020 | C34: 35251.2 | D34: 79682.4 | E34: 133416 | F34: 151164 | G34: 171360 | H34: 213465.6
B35: =B34+1 -> 2021 | C35: 18823.897 | D35: 64539.075 | E35: 99290.884 | F35: 120390.2 | G35: 127733.59
B36: =B35+1 -> 2022 | C36: 17258.4 | D36: 48654 | E36: 77112 | F36: 85374
B37: =B36+1 -> 2023 | C37: 7488.2281 | D37: 25093.53 | E37: 41025.931
B38: =B37+1 -> 2024 | C38: 6104.7 | D38: 19535.04
B39: =B38+1 -> 2025 | C39: 17772.48
B41: Amounts | C41: O/S Loss | E41: Development Age | I41: <== | J41: same as Case O/S
B42: AY | C42: 12 | D42: 24 | E42: 36 | F42: 48 | G42: 60 | H42: 72
B43: =B34 -> 2020 | C43: 64872 | D43: 51897.6 | E43: 39657.6 | F43: 25459.2 | G43: 22766.4 | H43: 0
B44: =B35 -> 2021 | C44: 65780.211 | D44: 47576.882 | E44: 31648.969 | F44: 21099.313 | G44: 18617.041
B45: =B36 -> 2022 | C45: 33782.4 | D45: 25061.4 | E45: 19094.4 | F45: 9730.8
B46: =B37 -> 2023 | C46: 25332.516 | D46: 24854.544 | E46: 17525.64
B47: =B38 -> 2024 | C47: 21773.43 | D47: 19535.04
B48: =B39 -> 2025 | C48: 15995.232
B50: Amounts | C50: Paid Count | E50: Development Age
B51: AY | C51: 12 | D51: 24 | E51: 36 | F51: 48 | G51: 60 | H51: 72
B52: =B43 -> 2020 | C52: 45.9 | D52: 107.1 | E52: 154.7 | F52: 198.9 | G52: 252.28 | H52: 280.16
B53: =B44 -> 2021 | C53: 31.28 | D53: 107.1 | E53: 178.5 | F53: 210.12 | G53: 240.89
B54: =B45 -> 2022 | C54: 35.36 | D54: 87.55 | E54: 130.56 | F54: 170
B55: =B46 -> 2023 | C55: 15.98 | D55: 55.59 | E55: 90.1
B56: =B47 -> 2024 | C56: 18.53 | D56: 55.08
B57: =B48 -> 2025 | C57: 35.7
...

Sheet 21
A1: 21 | B1: Incomplete | K1: Return to Point Grid
A3: Points
A4: =INDEX('Point Grid'!B:B,MATCH(A1,'Point Grid'!A:A,0)) -> 2.25
A6: (a) | B6: Calculate ultimate claims for all accident years using data as of year-end: | I6: =B14 -> 2023
A7: =INDEX('Point Grid'!$C$8:$I$54,MATCH($A$1,'Point Grid'!$A$8:$A$54,0),MATCH(A6,'Point Grid'!$C$7:$I$7,0)) -> 1
B9: cumulative paid claims
B10: AY | C10: 12 | D10: 24 | E10: 36 | F10: 48
B11: 2020 | C11: 1500 | D11: =ROUND(C11*1.5,0) -> 2250 | E11: =ROUND(D11*1.2,0) -> 2700 | F11: =ROUND(E11*1.1,0) -> 2970
B12: =B11+1 -> 2021 | C12: =ROUND(C11*1.03,0) -> 1545 | D12: =ROUND(C12*1.5,0) -> 2318 | E12: =ROUND(D12*1.2,0) -> 2782
B13: =B12+1 -> 2022 | C13: =ROUND(C12*1.03,0) -> 1591 | D13: =ROUND(C13*1.5,0) -> 2387
B14: =B13+1 -> 2023 | C14: =ROUND(C13*1.03,0) -> 1639
B16: Assume no development past 48 months. In other words, the triangle is fully dveloped by 48 months.
B18: The paid claims on the latest diagonal are in brown font for instructional purposes within the solution.
A20: (b) | B20: Identify the key assumption underlying the development method for estimating unpaid claims estimates.
A21: =INDEX('Point Grid'!$C$8:$I$54,MATCH($A$1,'Point Grid'!$A$8:$A$54,0),MATCH(A20,'Point Grid'!$C$7:$I$7,0)) -> 0.25
A24: (c) | B24: Identify whether each of the following triangles either satisfy or don't satisfy the key assumption of the development method.
A25: =INDEX('Point Grid'!$C$8:$I$54,MATCH($A$1,'Point Grid'!$A$8:$A$54,0),MATCH(A24,'Point Grid'!$C$7:$I$7,0)) -> 1
C26: Triangle 1 | D26: 12 | E26: 24 | F26: 36 | G26: 48
C27: 2020 | D27: 48.1 | E27: 141.2 | F27: 200.7 | G27: 240
C28: 2021 | D28: 47.4 | E28: 140.5 | F28: 201
C29: 2022 | D29: 48.2 | E29: 139.6
C30: 2023 | D30: 48
C32: Triangle 2 | D32: 12 | E32: 24 | F32: 36 | G32: 48
C33: 2020 | D33: 48 | E33: 140.4 | F33: 200.7 | G33: 240
C34: 2021 | D34: 43.6 | E34: 136 | F34: 198.6
C35: 2022 | D35: 40 | E35: 132.1
C36: 2023 | D36: 39.6
C38: Triangle 3 | D38: 12 | E38: 24 | F38: 36 | G38: 48
C39: 2020 | D39: 46.8 | E39: 144.3 | F39: 196.9 | G39: 240
C40: 2021 | D40: 53.3 | E40: 145.4 | F40: 203.1
C41: 2022 | D41: 60 | E41: 151.2
C42: 2023 | D42: 68.6
C44: Triangle 4 | D44: 12 | E44: 24 | F44: 36 | G44: 48
C45: 2020 | D45: 48 | E45: 140 | F45: 201 | G45: 240
C46: 2021 | D46: 52 | E46: 152 | F46: 217
C47: 2022 | D47: 56 | E47: 164
C48: 2023 | D48: 60

Sheet 22
A1: 22 | B1: Incomplete | J1: Return to Point Grid
A3: Points
A4: =INDEX('Point Grid'!B:B,MATCH(A1,'Point Grid'!A:A,0)) -> 1.75
A6: (a) | B6: Identify the key assumption of the Bornhuetter-Ferguson method for estimating unpaid claims.
A7: =INDEX('Point Grid'!$C$8:$I$54,MATCH($A$1,'Point Grid'!$A$8:$A$54,0),MATCH(A6,'Point Grid'!$C$7:$I$7,0)) -> 0.25
A10: (b) | B10: Identify 2 situations where the key assumption of the Bornhuetter-Ferguson method is likely to be
A11: =INDEX('Point Grid'!$C$8:$I$54,MATCH($A$1,'Point Grid'!$A$8:$A$54,0),MATCH(A10,'Point Grid'!$C$7:$I$7,0)) -> 0.5 | B11: satisfied.
A14: (c) | B14: Calculate the | D14: unpaid | E14: for AY | F14: 2024 | G14: using the Bornhuetter-Ferguson method.
A15: =INDEX('Point Grid'!$C$8:$I$54,MATCH($A$1,'Point Grid'!$A$8:$A$54,0),MATCH(A14,'Point Grid'!$C$7:$I$7,0)) -> 1
B17: All data is as of Dec 31, 2025 | G17: paid loss @ | H17: 12 mths | I17: 640
G18: reported loss @ | H18: 12 mths | I18: 1040
B19: EP for CY | C19: 2024 | D19: 1700 | G19: paid CDF for | H19: 12-ult | I19: 1.7
B20: ECR for AY | C20: 2024 | D20: 0.7 | G20: paid loss @ | H20: 24 mths | I20: 930
B21: EP for CY | C21: 2025 | D21: 800 | G21: reported loss @ | H21: 24 mths | I21: 1640
B22: ECR for AY | C22: 2025 | D22: 0.75 | G22: paid CDF for | H22: 24-ult | I22: 1.4

Sheet 23
A1: 23 | B1: Incomplete | I1: Return to Point Grid
A3: Points
A4: =INDEX('Point Grid'!B:B,MATCH(A1,'Point Grid'!A:A,0)) -> 3
A6: (a) | B6: The Cape Cod method for estimating unpaid claims has the same key assumption as the
A7: =INDEX('Point Grid'!$C$8:$I$54,MATCH($A$1,'Point Grid'!$A$8:$A$54,0),MATCH(A6,'Point Grid'!$C$7:$I$7,0)) -> 0.5 | B7: Bornhuetter-Ferguson method. Briefly explain the key difference between these 2 methods.
A10: (b) | B10: Identify and briefly explain 1 advantage and 1 disadvantage of the Cape Cod method.
A11: =INDEX('Point Grid'!$C$8:$I$54,MATCH($A$1,'Point Grid'!$A$8:$A$54,0),MATCH(A10,'Point Grid'!$C$7:$I$7,0)) -> 1
A14: (c) | B14: Calculate the | D14: ultimate | E14: for AY | F14: 2025 | G14: using the reported Cape Cod method.
A15: =INDEX('Point Grid'!$C$8:$I$54,MATCH($A$1,'Point Grid'!$A$8:$A$54,0),MATCH(A14,'Point Grid'!$C$7:$I$7,0)) -> 1.5
E17: pure
E18: premium
B19: AY | C19: rptd clms | D19: CDF | E19: trend | G19: CY | H19: EP
B20: 2023 | C20: 6400 | D20: 2.1 | E20: 1.079521 | G20: 2023 | H20: 17280
B21: 2024 | C21: 4000 | D21: 3.9 | E21: 1.039 | G21: 2024 | H21: 16400
B22: 2025 | C22: 1600 | D22: 5.4 | E22: 1 | G22: 2025 | H22: 12640
B24: * no rate level adjustments
B25: * no premium trend

Sheet 24
A1: 24 | B1: Incomplete | H1: Return to Point Grid
A3: Points
A4: =INDEX('Point Grid'!B:B,MATCH(A1,'Point Grid'!A:A,0)) -> 4.5
A6: (a) | B6: Identify and briefly describe 2 key assumptions of frequency-severity methods for estimating
A7: =INDEX('Point Grid'!$C$8:$I$54,MATCH($A$1,'Point Grid'!$A$8:$A$54,0),MATCH(A6,'Point Grid'!$C$7:$I$7,0)) -> 1 | B7: unpaid claims estimates.
A10: (b) | B10: Identify 1 advantage and 1 disadvantage of frequency-severity methods.
A11: =INDEX('Point Grid'!$C$8:$I$54,MATCH($A$1,'Point Grid'!$A$8:$A$54,0),MATCH(A10,'Point Grid'!$C$7:$I$7,0)) -> 1
A14: (c) | B14: Calculate the ultimate for AY 2025 using trended frequency and the given severity.
A15: =INDEX('Point Grid'!$C$8:$I$54,MATCH($A$1,'Point Grid'!$A$8:$A$54,0),MATCH(A14,'Point Grid'!$C$7:$I$7,0)) -> 2.5
B16: AY 2025 ultimate trended severity ==> | E16: 3419
B18: AY | C18: payroll (000s) | D18: reported | E18: ultimate | F18: ultimate
D19: claims (000s) | E19: counts | F19: severity
B20: 2022 | C20: 61000 | D20: 3170 | E20: 850 | F20: 2620
B21: 2023 | C21: 67900 | D21: 2100 | E21: 950 | F21: 2900
B22: 2024 | C22: 67800 | D22: 1400 | E22: 970 | F22: ?
B23: 2025 | C23: 71900 | D23: 900 | E23: ? | F23: ?
B25: exposure | C25: count | D25: severity
B26: trend | C26: trend | D26: trend
B27: 0.03 | C27: 0.02 | D27: 0.09
B29: 1 Use a simple weighted average for trend selections.
B30: 2 Data is as of Dec 31, 2025.

Sheet 25
A1: 25 | B1: Incomplete | H1: Return to Point Grid
A3: Points
A4: =INDEX('Point Grid'!B:B,MATCH(A1,'Point Grid'!A:A,0)) -> 2
A6: (a) | B6: The Friedland reserving text discusses 2 methods referred to as "Case Outstanding" methods. One of
A7: =INDEX('Point Grid'!$C$8:$I$54,MATCH($A$1,'Point Grid'!$A$8:$A$54,0),MATCH(A6,'Point Grid'!$C$7:$I$7,0)) -> 0.5 | B7: them is sometimes referred to as the "Development Method". The other case outstanding method
B8: is a formula that uses industry data to project a company's case outstanding amount assuming no
B9: other company data is available.
B11: Identify 2 specific situations where this "other" case outstanding method may be used.
A13: (b) | B13: Calculate the unpaid claim estimate for this self-insured entity for AY | H13: 2021
A14: =INDEX('Point Grid'!$C$8:$I$54,MATCH($A$1,'Point Grid'!$A$8:$A$54,0),MATCH(A13,'Point Grid'!$C$7:$I$7,0)) -> 1.5
B16: Information as of Dec 31, 2025:
C18: case O/S for AY | D18: 2021 | E18: 7970 | F18: <====== | G18: company data
B20: industry data | E20: paid | F20: reported
B21: 12 | C21: - ultimate | D21: CDF | E21: 4.55 | F21: 3.03
B22: 24 | C22: - ultimate | D22: CDF | E22: 2.2 | F22: 1.39
B23: 36 | C23: - ultimate | D23: CDF | E23: 1.59 | F23: 1.14
B24: 48 | C24: - ultimate | D24: CDF | E24: 1.24 | F24: 1.08
B25: 60 | C25: - ultimate | D25: CDF | E25: 1.13 | F25: 1.05
B26: 72 | C26: - ultimate | D26: CDF | E26: 1.09 | F26: 1.02

Sheet 26
A1: 26 | B1: Incomplete | L1: Return to Point Grid
A3: Points
A4: =INDEX('Point Grid'!B:B,MATCH(A1,'Point Grid'!A:A,0)) -> 2.25
A6: (a) | B6: Identify the purpose of the Berquist-Sherman reported method.
A7: =INDEX('Point Grid'!$C$8:$I$54,MATCH($A$1,'Point Grid'!$A$8:$A$54,0),MATCH(A6,'Point Grid'!$C$7:$I$7,0)) -> 0.25
A10: (b) | B10: Identify the purpose of the Berquist-Sherman paid method.
A11: =INDEX('Point Grid'!$C$8:$I$54,MATCH($A$1,'Point Grid'!$A$8:$A$54,0),MATCH(A10,'Point Grid'!$C$7:$I$7,0)) -> 0.25
A14: (c) | B14: Use the reported Berquist-Sherman method to calculate the | G14: unpaid | H14: for AY | I14: 2025
A15: =INDEX('Point Grid'!$C$8:$I$54,MATCH($A$1,'Point Grid'!$A$8:$A$54,0),MATCH(A14,'Point Grid'!$C$7:$I$7,0)) -> 1.75
C16: Cumulative Paid Loss ($000s) (CPL) | I16: Cumulative Reported Loss ($000s) (CRL)
B17: AY | C17: 12 | D17: 24 | E17: 36 | F17: 48 | H17: AY | I17: 12 | J17: 24 | K17: 36 | L17: 48
B18: 2022 | C18: 2520 | D18: 5784 | E18: 7796 | F18: 7409 | H18: =B18 -> 2022 | I18: 5198 | J18: 7425 | K18: 7311 | L18: 7409
B19: =B18+1 -> 2023 | C19: 2954 | D19: 6257 | E19: 7585 | H19: =H18+1 -> 2023 | I19: 5344 | J19: 7409 | K19: 7639
B20: =B19+1 -> 2024 | C20: 2712 | D20: 6107 | H20: =H19+1 -> 2024 | I20: 5292 | J20: 8505
B21: =B20+1 -> 2025 | C21: 2728 | H21: =H20+1 -> 2025 | I21: 6615
C23: Cumulative Paid Counts (CPC) | I23: Cumulative Reported Counts (CRC)
B24: AY | C24: 12 | D24: 24 | E24: 36 | F24: 48 | H24: AY | I24: 12 | J24: 24 | K24: 36 | L24: 48
B25: =B18 -> 2022 | C25: 344 | D25: 458 | E25: 523 | F25: 502 | H25: =B18 -> 2022 | I25: 491 | J25: 492 | K25: 518 | L25: 523
B26: =B25+1 -> 2023 | C26: 371 | D26: 519 | E26: 510 | H26: =H25+1 -> 2023 | I26: 489 | J26: 545 | K26: 556
B27: =B26+1 -> 2024 | C27: 334 | D27: 446 | H27: =H26+1 -> 2024 | I27: 487 | J27: 485
B28: =B27+1 -> 2025 | C28: 354 | H28: =H27+1 -> 2025 | I28: 501
B30: annual severity trend | F30: 0.04
B32: Hints: | C32: (You don't have to work everything out from scratch. Use the restated Average Case O/S shown below.)
C34: ORIGINAL Average Case O/S ($000s) (ACOS) | I34: RESTATED Average Case O/S (ACOS)
B35: AY | C35: 12 | D35: 24 | E35: 36 | F35: 48 | H35: AY | I35: 12 | J35: 24 | K35: 36 | L35: 48
B36: 2022 | C36: 18.2 | D36: 48.3 | E36: 97 | F36: 0 | H36: 2022 | I36: 23.5 | J36: 56.9 | K36: 1.2 | L36: 0
B37: 2023 | C37: 20.3 | D37: 44.3 | E37: 1.2 | H37: 2023 | I37: 24.4 | J37: 59.1 | K37: 1.2
B38: 2024 | C38: 16.9 | D38: 61.5 | H38: 2024 | I38: 25.4 | J38: 61.5
B39: 2025 | C39: 26.4 | H39: 2025 | I39: 26.4

Sheet 27
A1: 27 | B1: Incomplete | H1: Return to Point Grid
A3: Points
A4: =INDEX('Point Grid'!B:B,MATCH(A1,'Point Grid'!A:A,0)) -> 1.5
A6: (a) | B6: Alice the actuary drove her ATV (All-Terrian Vehicle) into a pond. It sunk to the bottom and was a total
A7: =INDEX('Point Grid'!$C$8:$I$54,MATCH($A$1,'Point Grid'!$A$8:$A$54,0),MATCH(A6,'Point Grid'!$C$7:$I$7,0)) -> 0.25 | B7: loss. Alice subsequently submitted a claim and her insurer paid her $3,500. The insurer then recovered
B8: the ATV and sold it for scrap, receiving $600. What was the insurer's net loss?
A10: (b) | B10: If an insurer has a gross loss of $500,000 but also has a reinsurance treaty with a quota-share
A11: =INDEX('Point Grid'!$C$8:$I$54,MATCH($A$1,'Point Grid'!$A$8:$A$54,0),MATCH(A10,'Point Grid'!$C$7:$I$7,0)) -> 0.25 | B11: percentage of 75% then what is the primary insurer's net loss, according to the Friedland text?
A14: (c) | B14: An insurer has 2 losses as shown below:
A15: =INDEX('Point Grid'!$C$8:$I$54,MATCH($A$1,'Point Grid'!$A$8:$A$54,0),MATCH(A14,'Point Grid'!$C$7:$I$7,0)) -> 0.5
C16: loss 1 | D16: 450
C17: loss 2 | D17: 600
B19: If the insurer has an excess-of-loss reinsurance treaty with an attachment point of 500 for individual
B20: losses then what is the primary insurer's reimbursement from the reinsurer?
A22: (d) | B22: Using the data from part (c), but assuming the attachment point applies to aggregate losses, what is
A23: =INDEX('Point Grid'!$C$8:$I$54,MATCH($A$1,'Point Grid'!$A$8:$A$54,0),MATCH(A22,'Point Grid'!$C$7:$I$7,0)) -> 0.5 | B23: the primary insurer's reimbursement from the reinsurer?

Sheet 28
A1: 28 | B1: Incomplete | H1: Return to Point Grid
A3: Points
A4: =INDEX('Point Grid'!B:B,MATCH(A1,'Point Grid'!A:A,0)) -> 3
A6: (a) | B6: Suppose you get to the end of your reserve analysis as of Dec 31, 2025 and have estimates of ultimates
A7: =INDEX('Point Grid'!$C$8:$I$54,MATCH($A$1,'Point Grid'!$A$8:$A$54,0),MATCH(A6,'Point Grid'!$C$7:$I$7,0)) -> 0.5 | B7: from several different methods:
C9: AY | D9: Paid | E9: Reported | F9: Paid | G9: Reported
D10: Development | E10: Development | F10: Berquist-Sherman | G10: Berquist-Sherman
C11: 2020 | D11: 1000 | E11: 1000 | F11: 1000 | G11: 1000
C12: 2021 | D12: 1000 | E12: 1000 | F12: 1000 | G12: 1000
C13: 2022 | D13: 1000 | E13: 1000 | F13: 1000 | G13: 1000
C14: 2023 | D14: 1000 | E14: 1050 | F14: 1000 | G14: 1000
C15: 2024 | D15: 1000 | E15: 1125 | F15: 1000 | G15: 1000
C16: 2025 | D16: 1000 | E16: 1300 | F16: 1000 | G16: 1000
B18: Why might the Paid Development and Berquist-Sherman methods show consistent estimates across all Accident Years (AYs),
B19: while the Reported Development method shows an increase starting from AY 2023?
A21: (b) | B21: Referring to part (a), what are the implications to a reserve analyst regarding the accuracy of the LDFs in the reported development method.
A22: =INDEX('Point Grid'!$C$8:$I$54,MATCH($A$1,'Point Grid'!$A$8:$A$54,0),MATCH(A21,'Point Grid'!$C$7:$I$7,0)) -> 0.5 | B22: Assume the selected LDFs are an arithmetic average of the values in each column of the LDF triangle.
A25: (c) | B25: Given the following information for an insurer as of Dec 31, 2023:
A26: =INDEX('Point Grid'!$C$8:$I$54,MATCH($A$1,'Point Grid'!$A$8:$A$54,0),MATCH(A25,'Point Grid'!$C$7:$I$7,0)) -> 0.5
B27: * | C27: Company management strengthened case reserves on all open claims during 2016.
B28: * | C28: Six unusually large claims that occurred in 2022 have been and closed, and there are no other large losses in the insurer's
C29: history
B30: * | C30: No adjustments were made to historical claims development factors.
B32: Briefly assess the appropriateness of each reserving method for AY 2020.
B34: (i) | C34: Paid development method
B35: (ii) | C35: Reported development method
A37: (d) | B37: Calculate the emergence of paid claims in the period | E37: 48 | F37: to | G37: 60 | H37: months.
A38: =INDEX('Point Grid'!$C$8:$I$54,MATCH($A$1,'Point Grid'!$A$8:$A$54,0),MATCH(A37,'Point Grid'!$C$7:$I$7,0)) -> 1.5
B40: Here is the current information for a particular AY:
B42: paid | C42: claims | D42: at | E42: 48 | F42: months | G42: 4570
B44: 12 | C44: - ultimate | D44: CDF | E44: 2.56
B45: 24 | C45: - ultimate | D45: CDF | E45: 1.34
B46: 36 | C46: - ultimate | D46: CDF | E46: 1.1
B47: 48 | C47: - ultimate | D47: CDF | E47: 1.04
B48: 60 | C48: - ultimate | D48: CDF | E48: 1.02
B49: 72 | C49: - ultimate | D49: CDF | E49: 1.01

Sheet 29
A1: 29 | B1: Incomplete | M1: Return to Point Grid
A3: Points
A4: =INDEX('Point Grid'!B:B,MATCH(A1,'Point Grid'!A:A,0)) -> 2
A6: (a) | B6: Use the | C6: additive | E6: approach to estimate the | H6: ultimate | I6: ALAE | J6: for AY | K6: =B22 -> 2023
A7: =INDEX('Point Grid'!$C$8:$I$54,MATCH($A$1,'Point Grid'!$A$8:$A$54,0),MATCH(A6,'Point Grid'!$C$7:$I$7,0)) -> 2
B8: cumulative paid claims: | H8: cumulative paid ALAE:
B10: AY | C10: 12 | D10: 24 | E10: 36 | F10: 48 | H10: AY | I10: 12 | J10: 24 | K10: 36 | L10: 48
B11: =B12-1 -> 2020 | C11: 7200 | D11: 21600 | E11: 31800 | F11: 34300 | H11: =B11 -> 2020 | I11: 173 | J11: 676 | K11: 1049 | L11: 1177
B12: =B13-1 -> 2021 | C12: 7500 | D12: 24300 | E12: 36800 | H12: =B12 -> 2021 | I12: 165 | J12: 665 | K12: 1075
B13: =B14-1 -> 2022 | C13: 7200 | D13: 22000 | H13: =B13 -> 2022 | I13: 151 | J13: 602
B14: 2023 | C14: 7900 | H14: =B14 -> 2023 | I14: 205
B16: selected ultimate claims by AY
B18: AY | C18: ult clms
B19: =B11 -> 2020 | C19: 34300
B20: =B12 -> 2021 | C20: 39693
B21: =B13 -> 2022 | C21: 35436
B22: =B14 -> 2023 | C22: 39427
B24: When selecting development factors, you may select a SIMPLE AVERAGE in this problem.

Sheet 30
A1: 30 | B1: Incomplete | L1: Return to Point Grid
A3: Points
A4: =INDEX('Point Grid'!B:B,MATCH(A1,'Point Grid'!A:A,0)) -> 2.5
A6: (a) | B6: Fullly describe why the classical formula for estimating unpaid ULAE may not be an accurate
A7: =INDEX('Point Grid'!$C$8:$I$54,MATCH($A$1,'Point Grid'!$A$8:$A$54,0),MATCH(A6,'Point Grid'!$C$7:$I$7,0)) -> 0.75 | B7: method, particularly in relation to fixed expenses like building rent.
A10: (b) | B10: Use the | C10: classical | E10: approach to estimate the | H10: unpaid | I10: ULAE | J10: CY | K10: 2023
A11: =INDEX('Point Grid'!$C$8:$I$54,MATCH($A$1,'Point Grid'!$A$8:$A$54,0),MATCH(A10,'Point Grid'!$C$7:$I$7,0)) -> 1.75
C12: occurrence | E12: <== policy type
D14: paid | E14: paid | F14: incurred | G14: <== incurred includes reported & IBNR
C15: CY | D15: ULAE | E15: claims | F15: claims
C16: 2019 | D16: 0 | E16: 0 | F16: 0
C17: 2020 | D17: 58000 | E17: 433000 | F17: 540000
C18: 2021 | D18: 42000 | E18: 350000 | F18: 460000
C19: 2022 | D19: 40000 | E19: 354000 | F19: 480000
C20: 2023 | D20: 42000 | E20: 441000 | F20: 430000
C22: 174000 | D22: case outstanding (latest AY)
C23: 51000 | D23: total IBNR (latest AY)
C24: 0.43 | D24: % of total IBNR attributed to future case development on known claims
C26: 0.6 | D26: percent of unallocated work that occurs when a claim is opened
C27: 0.4 | D27: percent of unallocated work that occurs when a claim is closed
